Workbook

Sheet Name
B4: Student Name | C4: Student ID
B5: Kush Anand Shah | C5: a1945524
B6: Supriya Abhijit Pingle | C6: a1944342
B7: Alan Sam Alelil | C7: a1930481
B8: Harikrishnan Manoj | C8: a1949187
B9: Chinmay Shetty | C9: a1916150
B10: Randeep Ravindra Pawar | C10: a1911485
B12: Sum ID | C12: 9681019

Sheet Income Sheet
B1: 2024 | C1: 2023 | D1: 2022 | E1: 2021 | F1: 2020 | H1: 2024 Adjusted | I1: 2023 Adjusted | J1: 2022 Adjusted | K1: 2021 Adjusted | L1: 2020 Adjusted | N1: 2024 (% Rev) | O1: 2023 (% Rev) | P1: 2022 (% Rev) | Q1: 2021 (% Rev) | R1: 2020 (% Rev) | S1: Average | U1: 2025 F | V1: 2026 F | W1: 2027 F | X1: 2028 F | Y1: 2029 F
A2: INCOME STATEMENT | H2: No adjustments for Income Statement
A3: Operating Revenue | B3: 8967.41 | C3: 8168.95 | D3: 9340.15 | E3: 8754.12 | F3: 6831.84 | N3: =B4/B3 -> 0.90387637 | O3: =C4/C3 -> 0.87524712 | P3: =D4/D3 -> 0.76870072 | Q3: =E4/E3 -> 0.78047708 | R3: =F4/F3 -> 0.88084616 | S3: =AVERAGE(N3:R4) -> 0.84182949 | U3: =Regression!L27 -> 9948.5409 | V3: =Regression!L28 -> 10340.633 | W3: =Regression!L29 -> 10868.869 | X3: =Regression!L30 -> 11328.863 | Y3: =Regression!L31 -> 11742.246
A4: Operating Expenses | B4: 8105.43 | C4: 7149.85 | D4: 7179.78 | E4: 6832.39 | F4: 6017.8 | U4: =U3*$S$3 -> 8374.9751 | V4: =V3*$S$3 -> 8705.0499 | W4: =W3*$S$3 -> 9149.7343 | X4: =X3*$S$3 -> 9536.9712 | Y4: =Y3*$S$3 -> 9884.9686
A5: EBITDA | B5: 861.97 | C5: 1019.1 | D5: 2160.37 | E5: 1921.73 | F5: 814.05 | U5: =U3-U4 -> 1573.5658 | V5: =V3-V4 -> 1635.5832 | W5: =W3-W4 -> 1719.1345 | X5: =X3-X4 -> 1791.8921 | Y5: =Y3-Y4 -> 1857.277
A6: Amortization | B6: 82.92 | C6: 71.63 | D6: 67.99 | E6: 68.2 | F6: 65.21 | N6: =B6/B3 -> 0.0092468171 | O6: =C6/C3 -> 0.0087685688 | P6: =D6/D3 -> 0.0072793263 | Q6: =E6/E3 -> 0.0077906174 | R6: =F6/F3 -> 0.0095450128 | S6: =AVERAGE(N6:R6) -> 0.0085260685 | U6: =U3*$S$6 -> 84.821941 | V6: =V3*$S$6 -> 88.164946 | W6: =W3*$S$6 -> 92.66872 | X6: =X3*$S$6 -> 96.590664 | Y6: =Y3*$S$6 -> 100.11519
A7: Depriciation | B7: 694.39 | C7: 631.3 | D7: 607.43 | E7: 573.39 | F7: 540.66 | N7: =B7/B4 -> 0.08566973 | O7: =C7/C4 -> 0.088295559 | P7: =D7/D4 -> 0.084602871 | Q7: =E7/E4 -> 0.083922317 | R7: =F7/F4 -> 0.089843464 | S7: =AVERAGE(N7:R7) -> 0.086466788 | U7: =$S$7*H33 -> 263.88626 | V7: =$S$7*U33 -> 287.09605 | W7: =$S$7*V33 -> 298.41109 | X7: =$S$7*W33 -> 313.65497 | Y7: =$S$7*X33 -> 326.92954
A8: Operating Profit
A9: EBIT | B9: =B5-(B6+C7) -> 147.75 | C9: =C5-(C6+D7) -> 340.04 | D9: =D5-(D6+E7) -> 1518.99 | E9: =E5-(E6+F7) -> 1312.87 | F9: =F5-(F6+G7) -> 748.84 | U9: =U5-(U6+U7) -> 1224.8576 | V9: =V5-(V6+V7) -> 1260.3222 | W9: =W5-(W6+W7) -> 1328.0547 | X9: =X5-(X6+X7) -> 1381.6465 | Y9: =Y5-(Y6+Y7) -> 1430.2322
A10: Non-Operating Expenses
A11: Interest Expense | B11: 151.35 | C11: 87.02 | D11: 79.82 | E11: 92.52 | F11: 112.85 | N11: =B11/B3 -> 0.016877783 | O11: =C11/C3 -> 0.010652532 | P11: =D11/D3 -> 0.0085459013 | Q11: =E11/E3 -> 0.010568738 | R11: =F11/F3 -> 0.016518244 | S11: =AVERAGE(N11:R11) -> 0.01263264 | U11: =U$3*$S11 -> 125.67633 | V11: =V$3*$S11 -> 130.62949 | W11: =W$3*$S11 -> 137.3025 | X11: =X$3*$S11 -> 143.11345 | Y11: =Y$3*$S11 -> 148.33556
A12: Non-Recurring Adjustments - Non-Operating- Decrease/(Increase) | E12: 5.09 | F12: 11.09 | N12: =B12/B3 -> 0 | O12: =C12/C3 -> 0 | P12: =D12/D3 -> 0 | Q12: =E12/E3 -> 0.00058144051 | R12: =F12/F3 -> 0.0016232816 | S12: =AVERAGE(N12:R12) -> 0.00044094442 | U12: =U$3*$S12 -> 4.3867536 | V12: =V$3*$S12 -> 4.5596444 | W12: =W$3*$S12 -> 4.792567 | X12: =X$3*$S12 -> 4.995399 | Y12: =Y$3*$S12 -> 5.1776776
A13: Normalized Pre-tax Profit | B13: =B5-SUM(B11:B12) -> 710.62 | C13: 932.07 | D13: 2080.55 | E13: 1834.3 | F13: 712.29 | U13: =U5-SUM(U11:U12) -> 1443.5027 | V13: =V5-SUM(V11:V12) -> 1500.3941 | W13: =W5-SUM(W11:W12) -> 1577.0395 | X13: =X5-SUM(X11:X12) -> 1643.7832 | Y13: =Y5-SUM(Y11:Y12) -> 1703.7637
A14: Taxes
A15: Income Taxes | B15: 186.85 | C15: 223.26 | D15: 561.74 | E15: 480.94 | F15: 157.16 | N15: =B15/B13 -> 0.26293941 | O15: =C15/C13 -> 0.23953137 | P15: =D15/D13 -> 0.26999591 | Q15: =E15/E13 -> 0.26219266 | R15: =F15/F13 -> 0.22064047 | S15: =AVERAGE(N15:R15) -> 0.25105996 | U15: =U13*$S$15 -> 362.40574 | V15: =V13*$S$15 -> 376.68889 | W15: =W13*$S$15 -> 395.93147 | X15: =X13*$S$15 -> 412.68816 | Y15: =Y13*$S$15 -> 427.74686
A16: Net Income After Tax
A17: Net Income after Tax | B17: 543.8 | C17: 707.93 | D17: 1515.47 | E17: 1347.66 | F17: 541.9 | N17: =B17/B3 -> 0.060641813 | O17: =C17/C3 -> 0.086661076 | P17: =D17/D3 -> 0.16225328 | Q17: =E17/E3 -> 0.1539458 | R17: =F17/F3 -> 0.079319773 | S17: =AVERAGE(N17:R17) -> 0.10856435 | U17: =U13-U15 -> 1081.097 | V17: =V13-V15 -> 1123.7052 | W17: =W13-W15 -> 1181.108 | X17: =X13-X15 -> 1231.0951 | Y17: =Y13-Y15 -> 1276.0169
A18: After Tax Income/Expense
A19: Minority Interest | B19: 32.71 | C19: 22.95 | D19: 54.9 | E19: 32.62 | F19: 14.15 | N19: =B19/B3 -> 0.003647653 | O19: =C19/C3 -> 0.0028094186 | P19: =D19/D3 -> 0.0058778499 | Q19: =E19/E3 -> 0.0037262455 | R19: =F19/F3 -> 0.0020711843 | S19: =AVERAGE(N19:R19) -> 0.0036264703 | U19: =U3*$S$19 -> 36.078088 | V19: =V3*$S$19 -> 37.499999 | W19: =W3*$S$19 -> 39.41563 | X19: =X3*$S$19 -> 41.083786 | Y19: =Y3*$S$19 -> 42.582904
A20: Net Income | B20: 511.09 | C20: 684.98 | D20: 1460.57 | E20: 1315.04 | F20: 527.75 | N20: =B20/B3 -> 0.05699416 | O20: =C20/C3 -> 0.083851658 | P20: =D20/D3 -> 0.15637543 | Q20: =E20/E3 -> 0.15021955 | R20: =F20/F3 -> 0.077248589 | S20: =AVERAGE(N20:R20) -> 0.10493788 | U20: =U17+U19 -> 1117.1751 | V20: =V17+V19 -> 1161.2052 | W20: =W17+W19 -> 1220.5236 | X20: =X17+X19 -> 1272.1789 | Y20: =Y17+Y19 -> 1318.5998
A22: Balance sheet | H22: 2024 Adjusted | I22: 2023 Adjusted | J22: 2022 Adjusted | K22: 2021 Adjusted | L22: 2020 Adjusted | N22: 2024 (% Rev) | O22: 2023 (% Rev) | P22: 2022 (% Rev) | Q22: 2021 (% Rev) | R22: 2020 (% Rev) | S22: Average
A23: Current Assets
A24: Cash & Cash Equivalents | B24: 645 | C24: 797.99 | D24: 780 | E24: 899.83 | F24: 1230.15 | H24: 645 | I24: 797.99 | J24: 780 | K24: 899.83 | L24: 1230.15 | N24: =H24/$B$4 -> 0.079576284 | O24: =I24/$B$4 -> 0.098451285 | P24: =J24/$B$4 -> 0.096231785 | Q24: =K24/$B$4 -> 0.1110157 | R24: =L24/$B$4 -> 0.15176863 | S24: =AVERAGE(N24:R24) -> 0.10740874 | U24: =U54+U62-U38-U32-U31-U34 -> 2694.5166 | V24: =V54+V62-V38-V32-V31-V34 -> 2800.713 | W24: =W54+W62-W38-W32-W31-W34 -> 2943.7832 | X24: =X54+X62-X38-X32-X31-X34 -> 3068.3706 | Y24: =Y54+Y62-Y38-Y32-Y31-Y34 -> 3180.3333
A25: Loans & Receivables - Net - Short-Term | B25: 1362.18 | C25: 1022.18 | D25: 1217.46 | E25: 1088.72 | F25: 986.77 | H25: 1362.18 | I25: 1022.18 | J25: 1217.46 | K25: 1088.72 | L25: 986.77 | N25: =H25/$B$4 -> 0.16805771 | O25: =I25/$B$4 -> 0.12611052 | P25: =J25/$B$4 -> 0.15020301 | Q25: =K25/$B$4 -> 0.13431983 | R25: =L25/$B$4 -> 0.12174184 | S25: =AVERAGE(N25:R25) -> 0.14008658 | U25: =U3*$S$25 -> 1393.6571 | V25: =V3*$S$25 -> 1448.584 | W25: =W3*$S$25 -> 1522.5827 | X25: =X3*$S$25 -> 1587.0218 | Y25: =Y3*$S$25 -> 1644.9311
A26: Trade Accounts & Trade Notes Receivable - Net | B26: 910.89 | C26: 770.96 | D26: 930.94 | E26: 846.36 | F26: 713.74 | H26: 910.89 | I26: 770.96 | J26: 930.94 | K26: 846.36 | L26: 713.74 | N26: =H26/$B$4 -> 0.11238022 | O26: =I26/$B$4 -> 0.095116484 | P26: =J26/$B$4 -> 0.11485387 | Q26: =K26/$B$4 -> 0.10441889 | R26: =L26/$B$4 -> 0.088057019 | S26: =AVERAGE(N26:R26) -> 0.1029653 | U26: =U3*$S$26 -> 1024.3545 | V26: =V3*$S$26 -> 1064.7264 | W26: =W3*$S$26 -> 1119.1163 | X26: =X3*$S$26 -> 1166.4798 | Y26: =Y3*$S$26 -> 1209.0438
A27: Provision - Trade Accounts & Trade Notes Receivable | B27: 154.84 | C27: 171 | D27: 174.37 | E27: 191.57 | F27: 145.49 | H27: 154.84 | I27: 171 | J27: 174.37 | K27: 191.57 | L27: 145.49 | N27: =H27/$B$4 -> 0.019103243 | O27: =I27/$B$4 -> 0.021096968 | P27: =J27/$B$4 -> 0.021512739 | Q27: =K27/$B$4 -> 0.023634773 | R27: =L27/$B$4 -> 0.017949695 | S27: =AVERAGE(N27:R27) -> 0.020659484 | U27: =U3*$S$27 -> 205.53172 | V27: =V3*$S$27 -> 213.63214 | W27: =W3*$S$27 -> 224.54522 | X27: =X3*$S$27 -> 234.04847 | Y27: =Y3*$S$27 -> 242.58873
A28: Inventories - Total | B28: 208.83 | C28: 199.2 | D28: 216.19 | E28: 224.39 | F28: 163.43 | H28: 208.83 | I28: 199.2 | J28: 216.19 | K28: 224.39 | L28: 163.43 | N28: =H28/$B$4 -> 0.02576421 | O28: =I28/$B$4 -> 0.024576117 | P28: =J28/$B$4 -> 0.026672243 | Q28: =K28/$B$4 -> 0.027683911 | R28: =L28/$B$4 -> 0.020163027 | S28: =AVERAGE(N28:R28) -> 0.024971902 | U28: =U3*$S$28 -> 248.43398 | V28: =V3*$S$28 -> 258.22527 | W28: =W3*$S$28 -> 271.41632 | X28: =X3*$S$28 -> 282.90326 | Y28: =Y3*$S$28 -> 293.2262
A29: Total Current Assets | B29: =SUM(B24:B28) -> 3281.74 | C29: =SUM(C24:C28) -> 2961.33 | D29: =SUM(D24:D28) -> 3318.96 | E29: =SUM(E24:E28) -> 3250.87 | F29: =SUM(F24:F28) -> 3239.58 | H29: =SUM(H24:H28) -> 3281.74 | I29: =SUM(I24:I28) -> 2961.33 | J29: =SUM(J24:J28) -> 3318.96 | K29: =SUM(K24:K28) -> 3250.87 | L29: =SUM(L24:L28) -> 3239.58 | U29: =SUM(U24:U28) -> 5566.4939 | V29: =SUM(V24:V28) -> 5785.8807 | W29: =SUM(W24:W28) -> 6081.4438 | X29: =SUM(X24:X28) -> 6338.8238 | Y29: =SUM(Y24:Y28) -> 6570.1231
A30: Non-Current Assets
A31: Investments - Long-Term | B31: 198.35 | C31: 175.8 | D31: 145.22 | E31: 108.11 | F31: 91.75 | H31: 198.35 | I31: 175.8 | J31: 145.22 | K31: 108.11 | L31: 91.75 | N31: =H31/$B$4 -> 0.02447125 | O31: =I31/$B$4 -> 0.021689164 | P31: =J31/$B$4 -> 0.017916384 | Q31: =K31/$B$4 -> 0.013337972 | R31: =L31/$B$4 -> 0.011319572 | S31: =AVERAGE(N31:R31) -> 0.017746868 | U31: =U$3*$S31 -> 176.55545 | V31: =V$3*$S31 -> 183.51386 | W31: =W$3*$S31 -> 192.88839 | X31: =X$3*$S31 -> 201.05185 | Y31: =Y$3*$S31 -> 208.38809
A32: Receivables & Loans - Long-Term | B32: 22.24 | C32: 37.74 | D32: 38.19 | E32: 31.55 | F32: 50.43 | H32: 22.24 | I32: 37.74 | J32: 38.19 | K32: 31.55 | L32: 50.43 | N32: =H32/$B$4 -> 0.0027438396 | O32: =I32/$B$4 -> 0.0046561379 | P32: =J32/$B$4 -> 0.0047116563 | Q32: =K32/$B$4 -> 0.0038924523 | R32: =L32/$B$4 -> 0.006221755 | S32: =AVERAGE(N32:R32) -> 0.0044451682 | U32: =U$3*$S32 -> 44.222938 | V32: =V$3*$S32 -> 45.965854 | W32: =W$3*$S32 -> 48.31395 | X32: =X$3*$S32 -> 50.358703 | Y32: =Y$3*$S32 -> 52.196257
A33: PPE | B33: 3051.88 | C33: 2798.11 | D33: 2624.86 | E33: 2552.92 | F33: 2498.08 | H33: 3051.88 | I33: 2798.11 | J33: 2624.86 | K33: 2552.92 | L33: 2498.08 | N33: =H33/$B$4 -> 0.3765229 | O33: =I33/$B$4 -> 0.34521426 | P33: =J33/$B$4 -> 0.3238397 | Q33: =K33/$B$4 -> 0.31496417 | R33: =L33/$B$4 -> 0.30819833 | S33: =AVERAGE(N33:R33) -> 0.33374787 | U33: =U$3*$S33 -> 3320.3043 | V33: =V$3*$S33 -> 3451.1643 | W33: =W$3*$S33 -> 3627.4618 | X33: =X$3*$S33 -> 3780.984 | Y33: =Y$3*$S33 -> 3918.9494
A34: Other Non-Current Assets - Total | B34: 74.75 | C34: 80.19 | D34: 76.34 | E34: 71.58 | F34: 76.86 | H34: 74.75 | I34: 80.19 | J34: 76.34 | K34: 71.58 | L34: 76.86 | N34: =H34/$B$4 -> 0.0092222128 | O34: =I34/$B$4 -> 0.0098933678 | P34: =J34/$B$4 -> 0.0094183776 | Q34: =K34/$B$4 -> 0.0088311169 | R34: =L34/$B$4 -> 0.0094825321 | S34: =AVERAGE(N34:R34) -> 0.0093695214 | U34: =U$3*$S34 -> 93.213067 | V34: =V$3*$S34 -> 96.886784 | W34: =W$3*$S34 -> 101.8361 | X34: =X$3*$S34 -> 106.14603 | Y34: =Y$3*$S34 -> 110.01922
A35: Deferred Tax - Asset - Long-Term | B35: 65.94 | C35: 72.38 | D35: 68.99 | E35: 65.28 | F35: 70.76 | H35: 0 | I35: 0 | J35: 0 | K35: 0 | L35: 0 | N35: =H35/$B$4 -> 0 | O35: =I35/$B$4 -> 0 | P35: =J35/$B$4 -> 0 | Q35: =K35/$B$4 -> 0 | R35: =L35/$B$4 -> 0 | S35: =AVERAGE(N35:R35) -> 0 | U35: 0 | V35: 0 | W35: 0 | X35: 0 | Y35: 0
A36: Goodwill/Cost in Excess of Assets Purchased - Net | B36: 8405.12 | C36: 7237.43 | D36: 6852.96 | E36: 6231.85 | F36: 6486.33 | H36: 8405.12 | I36: 7237.43 | J36: 6852.96 | K36: 6231.85 | L36: 6486.33 | N36: =H36/$B$4 -> 1.036974 | O36: =I36/$B$4 -> 0.8929113 | P36: =J36/$B$4 -> 0.84547766 | Q36: =K36/$B$4 -> 0.76884878 | R36: =L36/$B$4 -> 0.80024502 | S36: =AVERAGE(N36:R36) -> 0.86889135 | U36: =U$3*$S36 -> 8644.2011 | V36: =V$3*$S36 -> 8984.8867 | W36: =W$3*$S36 -> 9443.8661 | X36: =X$3*$S36 -> 9843.5513 | Y36: =Y$3*$S36 -> 10202.736
A37: Intangible Assets - excluding Goodwill - Net - Total | B37: 721.15 | C37: 552.19 | D37: 508.52 | E37: 480.4 | F37: 468.57 | H37: =B37*25% -> 180.2875 | I37: =C37*25% -> 138.0475 | J37: =D37*25% -> 127.13 | K37: =E37*25% -> 120.1 | L37: =F37*25% -> 117.1425 | N37: =H37/$B$4 -> 0.022242805 | O37: =I37/$B$4 -> 0.017031484 | P37: =J37/$B$4 -> 0.015684547 | Q37: =K37/$B$4 -> 0.014817227 | R37: =L37/$B$4 -> 0.014452349 | S37: =AVERAGE(N37:R37) -> 0.016845682 | U37: =U$3*$S37 -> 167.58996 | V37: =V$3*$S37 -> 174.19502 | W37: =W$3*$S37 -> 183.09351 | X37: =X$3*$S37 -> 190.84243 | Y37: =Y$3*$S37 -> 197.80614
A38: Total Non-Current Assets | B38: =SUM(B31,B32,B33,B34,B36,B37) -> 12473.49 | C38: =SUM(C31,C32,C33,C34,C36,C37) -> 10881.46 | D38: =SUM(D31,D32,D33,D34,D36,D37) -> 10246.09 | E38: =SUM(E31,E32,E33,E34,E36,E37) -> 9476.41 | F38: =SUM(F31,F32,F33,F34,F36,F37) -> 9672.02 | H38: =SUM(H31:H37) -> 11932.628 | I38: =SUM(I31:I37) -> 10467.318 | J38: =SUM(J31:J37) -> 9864.7 | K38: =SUM(K31:K37) -> 9116.11 | L38: =SUM(L31:L37) -> 9320.5925 | U38: =SUM(U31:U37) -> 12446.087 | V38: =SUM(V31:V37) -> 12936.612 | W38: =SUM(W31:W37) -> 13597.46 | X38: =SUM(X31:X37) -> 14172.934 | Y38: =SUM(Y31:Y37) -> 14690.095
A39: Total Assets
A40: Total Assets | B40: =B29+B38 -> 15755.23 | C40: =C29+C38 -> 13842.79 | D40: =D29+D38 -> 13565.05 | E40: =E29+E38 -> 12727.28 | F40: =F29+F38 -> 12911.6 | H40: =H29+H38 -> 15214.368 | I40: =I29+I38 -> 13428.648 | J40: =J29+J38 -> 13183.66 | K40: =K29+K38 -> 12366.98 | L40: =L29+L38 -> 12560.173
A41: Current Liabilities
...

Sheet Dividend Calculation
A1: Dividend calculation | G1: DPR=1-r
A2: Year | B2: Earnings | C2: RE (t-1) | D2: RE (t) | E2: Div Dist | F2: Retention Ratio | G2: Dividend payout ratio | H2: Assumed min 0% and max 100% as per instruction manual
A3: 2020 | B3: ='Income Sheet'!F20 -> 527.75 | C3: 1287 | D3: ='Income Sheet'!F57 -> 1385.12 | E3: =C3+B3-D3 -> 429.63 | F3: =1-G3 -> 0.18592136 | G3: =E3/B3 -> 0.81407864 | H3: 1
A4: 2021 | B4: ='Income Sheet'!E20 -> 1315.04 | C4: 1385.12 | D4: ='Income Sheet'!E57 -> 2310.5 | E4: =C4+B4-D4 -> 389.66 | F4: =1-G4 -> 0.70368962 | G4: =E4/B4 -> 0.29631038 | H4: 1
A5: 2022 | B5: ='Income Sheet'!D20 -> 1460.57 | C5: 2310.5 | D5: ='Income Sheet'!D57 -> 3339.04 | E5: =C5+B5-D5 -> 432.03 | F5: =1-G5 -> 0.70420452 | G5: =E5/B5 -> 0.29579548 | H5: 1
A6: 2023 | B6: ='Income Sheet'!C20 -> 684.98 | C6: 3339.04 | D6: 3519.9 | E6: =C6+B6-D6 -> 504.12 | F6: =1-G6 -> 0.26403691 | G6: =E6/B6 -> 0.73596309 | H6: 1
A7: 2024 | B7: ='Income Sheet'!B20 -> 511.09 | C7: 3519.9 | D7: ='Income Sheet'!B57 -> 3516.69 | E7: =C7+B7-D7 -> 514.3 | F7: =1-G7 -> -0.0062806942 | G7: =E7/B7 -> 1.0062807 | H7: 1 | I7: Average | J7: 1
A8: 2025 | B8: ='Income Sheet'!U20 -> 1117.1751 | C8: =D7 -> 3516.69 | D8: ='Income Sheet'!U57 -> 9318.4027 | E8: =B8*$J$7 -> 1117.1751 | F8: =1-G8 -> 0 | G8: =E8/B8 -> 1
A9: 2026 | B9: ='Income Sheet'!V20 -> 1161.2052 | C9: =D8 -> 9318.4027 | D9: ='Income Sheet'!V57 -> 9685.6599 | E9: =B9*$J$7 -> 1161.2052 | F9: =1-G9 -> 0 | G9: =E9/B9 -> 1
A10: 2027 | B10: ='Income Sheet'!W20 -> 1220.5236 | C10: =D9 -> 9685.6599 | D10: ='Income Sheet'!W57 -> 10180.437 | E10: =B10*$J$7 -> 1220.5236 | F10: =1-G10 -> 0 | G10: =E10/B10 -> 1
A11: 2028 | B11: ='Income Sheet'!X20 -> 1272.1789 | C11: =D10 -> 10180.437 | D11: ='Income Sheet'!X57 -> 10611.296 | E11: =B11*$J$7 -> 1272.1789 | F11: =1-G11 -> 0 | G11: =E11/B11 -> 1
A12: 2029 | B12: ='Income Sheet'!Y20 -> 1318.5998 | C12: =D11 -> 10611.296 | D12: ='Income Sheet'!Y57 -> 10998.495 | E12: =B12*$J$7 -> 1318.5998 | F12: =1-G12 -> 0 | G12: =E12/B12 -> 1

Sheet Section B
C3: Market Capitalisation
C4: Company | D4: ASX Code | E4: Market Capitalisation (AUD)
C5: Sonic Healthcare Ltd | D5: SHL | E5: 12820000000
C6: Ramsay Healthcare Ltd | D6: RHC | E6: 8730000000
C7: Healius Ltd | D7: HLS | E7: 635370000
C8: Mean | E8: =AVERAGE(E5:E7) -> 7.3951233e+09
C9: Median | E9: =MEDIAN(E5:E7) -> 8730000000
C10: As at 02/06/2025
C13: Peer Ratios (Outputs)
C14: Company | D14: ASX Code | E14: Trailing P/E Ratio | F14: Leading P/E Ratio | G14: PEG Ratio | H14: P/B Ratio
C15: Sonic Healthcare Ltd | D15: SHL | E15: 23.45 | F15: 21.28 | G15: =E15*((1-(G27))*H27) -> 0 | H15: 1.56
C16: Ramsay Healthcare Ltd | D16: RHC | E16: 489 | F16: 26.04 | G16: =E16*((1-(G28))*H28) -> 0.457704 | H16: 1.91
C17: Healius Ltd | D17: HLS | E17: 60.94 | F17: 78.74 | G17: =E17*((1-(G29))*H29) -> -1.1017708 | H17: 0.62
C18: Mean | E18: =AVERAGE(E15:E17) -> 191.13 | F18: =AVERAGE(F15:F17) -> 42.02 | G18: =AVERAGE(G15:G17) -> -0.21468894 | H18: =AVERAGE(H15:H17) -> 1.3633333
C19: Median | E19: =MEDIAN(E15:E17) -> 60.94 | F19: =MEDIAN(F15:F17) -> 26.04 | G19: =MEDIAN(G15:G17) -> 0 | H19: =MEDIAN(H15:H17) -> 1.56
C20: Sonic Healthcare Limited - Relative Valuation | E20: Overvalued | F20: Overvalued | G20: Overvalued | H20: Overvalued
C21: Formula Description | E21: P / EPS | F21: P / Forecasted EPS | G21: Trailing P/E/ g B = 1-DPR g = B x ROE Thus, Trailing P/E Ratio * g | H21: P / BVPS
C22: As at 02/06/2025
C25: Peer Ratios (Inputs) - For Appendix
C26: Company | D26: ASX Code | E26: EPS | F26: Forecasted EPS (2024) | G26: Dividend Payout Ratio | H26: ROE | I26: Equity | J26: Outstanding Shares | K26: Book Value Per Share
C27: Sonic Healthcare Ltd | D27: SHL | E27: 1.07 | F27: 1.091 | G27: ='Dividend Calculation'!G8 -> 1 | H27: 0.0716 | I27: 7917623 | J27: 480400000 | K27: 17.07
C28: Ramsay Healthcare Ltd | D28: RHC | E28: 3.89 | F28: 1.242 | G28: 0.82 | H28: 0.0052 | I28: 4897600 | J28: 230840000 | K28: 19.92
C29: Healius Ltd | D29: HLS | E29: -0.98 | F29: -0.02 | G29: 0.413 | H29: -0.0308 | I29: 1040700 | J29: 726130000 | K29: 1.41
C30: As at 02/06/2025
C31: Source: Refinitiv Workspace & Yahoo finance
C36: Fundamental Ratios (Inputs) - For Appendix
C37: Company | D37: ASX Code | E37: EPS | F37: Forecasted EPS (2024) | G37: Dividend Payout Ratio | H37: ROE | I37: Equity | J37: Outstanding Shares | K37: Book Value Per Share | L37: Cost of Equity | M37: Growth Rate (gh) | N37: Retention Ratio | O37: Sustainable Growth Rate (gs)
C38: Sonic Healthcare Ltd | D38: SHL | E38: =E27 -> 1.07 | F38: =F27 -> 1.091 | G38: =G27 -> 1 | H38: =H27 -> 0.0716 | I38: =I27 -> 7917623 | J38: =J27 -> 480400000 | K38: =K27 -> 17.07 | L38: 0.06 | M38: =((1-(G27))*H27) -> 0 | N38: =1-G38 -> 0 | O38: 0.03
C39: Ramsay Healthcare Ltd | D39: RHC | E39: =E28 -> 3.89 | F39: =F28 -> 1.242 | G39: =G28 -> 0.82 | H39: =H28 -> 0.0052 | I39: =I28 -> 4897600 | J39: =J28 -> 230840000 | K39: =K28 -> 19.92 | L39: 0.076 | M39: =((1-(G28))*H28) -> 0.000936 | N39: =1-G39 -> 0.18 | O39: 0.03
C40: Healius Ltd | D40: HLS | E40: =E29 -> -0.98 | F40: =F29 -> -0.02 | G40: =G29 -> 0.413 | H40: =H29 -> -0.0308 | I40: =I29 -> 1040700 | J40: =J29 -> 726130000 | K40: =K29 -> 1.41 | L40: 0.0787 | M40: =((1-(G29))*H29) -> -0.0180796 | N40: =1-G40 -> 0.587 | O40: 0.03
C41: As at 02/06/2025
C42: Source: Refinitiv Workspace & Yahoo finance
C46: Market Capitalisation
C47: Company | D47: ASX Code | E47: Market Capitalisation (AUD)
C48: Sonic Healthcare Ltd | D48: SHL | E48: =E5 -> 12820000000
C49: Ramsay Healthcare Ltd | D49: RHC | E49: =E6 -> 8730000000
C50: Healius Ltd | D50: HLS | E50: =E7 -> 635370000
C51: Mean | E51: =E8 -> 7.3951233e+09
C52: Median | E52: =E9 -> 8730000000
C53: As at 02/06/2025
...

Sheet Regression
A1: Year | B1: Nominal Operating Revenue | C1: CPI | D1: Real Operating Revenue | I1: Real GDP ($ million) | J1: Real Operating Revenue
A2: 2000 | B2: 387.6 | C2: 71.475 | D2: =B2*$C$26/C2 -> 752.01721 | I2: 1037818 | J2: =D2 -> 752.01721
A3: 2001 | B3: 625.8 | C3: 74.625 | D3: =B3*$C$26/C3 -> 1162.9188 | I3: 1416147 | J3: =D3 -> 1162.9188
A4: 2002 | B4: 855.8 | C4: 76.85 | D4: =B4*$C$26/C4 -> 1544.2819 | I4: 1475047 | J4: =D4 -> 1544.2819 | M4: SUMMARY OUTPUT
A5: 2003 | B5: 972.1 | C5: 78.95 | D5: =B5*$C$26/C5 -> 1707.4853 | I5: 1519528 | J5: =D5 -> 1707.4853
A6: 2004 | B6: 1032.4 | C6: 80.8 | D6: =B6*$C$26/C6 -> 1771.8821 | I6: 1582030 | J6: =D6 -> 1771.8821 | M6: Regression Statistics
A7: 2005 | B7: 1380.5 | C7: 82.975 | D7: =B7*$C$26/C7 -> 2307.2111 | I7: 1629954 | J7: =D7 -> 2307.2111 | M7: Multiple R | N7: 0.95895076
A8: 2006 | B8: 1651.7 | C8: 85.925 | D8: =B8*$C$26/C8 -> 2665.691 | I8: 1672660 | J8: =D8 -> 2665.691 | M8: R Square | N8: 0.91958656
A9: 2007 | B9: 1886.1 | C9: 87.925 | D9: =B9*$C$26/C9 -> 2974.7503 | I9: 1745241 | J9: =D9 -> 2974.7503 | M9: Adjusted R Square | N9: 0.91609032
A10: 2008 | B10: 2378.9 | C10: 91.75 | D10: =B10*$C$26/C10 -> 3595.5745 | I10: 1790517 | J10: =D10 -> 3595.5745 | M10: Standard Error | N10: 815.10067
A11: 2009 | B11: 3013.5 | C11: 93.375 | D11: =B11*$C$26/C11 -> 4475.4711 | I11: 1825693 | J11: =D11 -> 4475.4711 | M11: Observations | N11: 25
A12: 2010 | B12: 2989.4 | C12: 96.1 | D12: =B12*$C$26/C12 -> 4313.7882 | I12: 1869858 | J12: =D12 -> 4313.7882
A13: 2011 | B13: 3096.2 | C13: 99.275 | D13: =B13*$C$26/C13 -> 4325.0117 | I13: 1921941 | J13: =D13 -> 4325.0117 | M13: ANOVA
A14: 2012 | B14: 3345.6 | C14: 101.025 | D14: =B14*$C$26/C14 -> 4592.4383 | I14: 1994764 | J14: =D14 -> 4592.4383 | N14: df | O14: SS | P14: MS | Q14: F | R14: Significance F
A15: 2013 | B15: 3484.1 | C15: 103.5 | D15: =B15*$C$26/C15 -> 4668.1891 | I15: 2039027 | J15: =D15 -> 4668.1891 | M15: Regression | N15: 1 | O15: 1.7474884e+08 | P15: 1.7474884e+08 | Q15: 263.02184 | R15: 4.4089269e-14
A16: 2014 | B16: 3913.5 | C16: 106.075 | D16: =B16*$C$26/C16 -> 5116.2349 | I16: 2091528 | J16: =D16 -> 5116.2349 | M16: Residual | N16: 23 | O16: 15280949 | P16: 664389.1
A17: 2015 | B17: 4200.5 | C17: 107.675 | D17: =B17*$C$26/C17 -> 5409.8383 | I17: 2140476 | J17: =D17 -> 5409.8383 | M17: Total | N17: 24 | O17: 1.9002979e+08
A18: 2016 | B18: 5017.7 | C18: 109.05 | D18: =B18*$C$26/C18 -> 6380.8303 | I18: 2198144 | J18: =D18 -> 6380.8303
A19: 2017 | B19: 5122.1 | C19: 111.175 | D19: =B19*$C$26/C19 -> 6389.0912 | I19: 2250465 | J19: =D19 -> 6389.0912 | N19: Coefficients | O19: Standard Error | P19: t Stat | Q19: P-value | R19: Lower 95% | S19: Upper 95% | T19: Lower 95.0% | U19: Upper 95.0%
A20: 2018 | B20: 5541.4 | C20: 113.3 | D20: =B20*$C$26/C20 -> 6782.4682 | I20: 2313275 | J20: =D20 -> 6782.4682 | M20: Intercept | N20: -8078.0726 | O20: 820.81867 | P20: -9.8414826 | Q20: 1.0325671e-09 | R20: -9776.0654 | S20: -6380.0799 | T20: -9776.0654 | U20: -6380.0799
A21: 2019 | B21: 6133.7 | C21: 115.125 | D21: =B21*$C$26/C21 -> 7388.4113 | E21: CPI Growth | G21: Taking the past 5 year average GDP | H21: GDP growth | I21: 2358070 | J21: =D21 -> 7388.4113 | M21: X Variable 1 | N21: 0.0066071064 | O21: 0.00040739471 | P21: 16.217948 | Q21: 4.4089269e-14 | R21: 0.0057643462 | S21: 0.0074498665 | T21: 0.0057643462 | U21: 0.0074498665
A22: 2020 | B22: 6831.8 | C22: 116.1 | D22: =B22*$C$26/C22 -> 8160.2056 | E22: =C22/C21-1 -> 0.0084690554 | H22: =I22/I21-1 -> -0.01954819 | I22: 2311974 | J22: =D22 -> 8160.2056
A23: 2021 | B23: 8754.1 | C23: 119.425 | D23: =B23*$C$26/C23 -> 10165.165 | E23: =C23/C22-1 -> 0.028639104 | H23: =I23/I22-1 -> 0.054115228 | I23: 2437087 | J23: =D23 -> 10165.165
A24: 2022 | B24: 9340.2 | C24: 127.3 | D24: =B24*$C$26/C24 -> 10174.802 | E24: =C24/C23-1 -> 0.065940967 | H24: =I24/I23-1 -> 0.041419941 | I24: 2538031 | J24: =D24 -> 10174.802
A25: 2023 | B25: 8169 | C25: 134.425 | D25: =B25*$C$26/C25 -> 8427.2723 | E25: =C25/C24-1 -> 0.055970149 | H25: =I25/I24-1 -> 0.020557275 | I25: 2590206 | J25: =D25 -> 8427.2723
A26: 2024 | B26: 8967.4 | C26: 138.675 | D26: =B26*$C$26/C26 -> 8967.4 | E26: =C26/C25-1 -> 0.031616143 | H26: =I26/I25-1 -> 0.010382572 | I26: 2617099 | J26: =D26 -> 8967.4 | K26: Inflation | L26: Nominal Operating Revenue
A27: 2025 | E27: =AVERAGE(E22:E26) -> 0.038127084 | H27: =AVERAGE(H21:H26) -> 0.021385365 | I27: =I26+(I26*H27) -> 2673066.6 | J27: =$N$20+($N$21*I27) -> 9583.1628 | K27: =E27 -> 0.038127084 | L27: =J27*(1+K27) -> 9948.5409
A28: 2026 | H28: =AVERAGE(H22:H27) -> 0.021385365 | I28: =I27+(I27*H28) -> 2730231.1 | J28: =$N$20+($N$21*I28) -> 9960.8548 | K28: =E27 -> 0.038127084 | L28: =J28*(1+K28) -> 10340.633
A29: 2027 | H29: =AVERAGE(H23:H28) -> 0.028207624 | I29: =I28+(I28*H29) -> 2807244.5 | J29: =$N$20+($N$21*I29) -> 10469.69 | K29: =E27 -> 0.038127084 | L29: =J29*(1+K29) -> 10868.869
A30: 2028 | H30: =AVERAGE(H24:H29) -> 0.02388969 | I30: =I29+(I29*H30) -> 2874308.7 | J30: =$N$20+($N$21*I30) -> 10912.79 | K30: =E27 -> 0.038127084 | L30: =J30*(1+K30) -> 11328.863
A31: 2029 | H31: =AVERAGE(H25:H30) -> 0.020967982 | I31: =I30+(I30*H31) -> 2934577.1 | J31: =$N$20+($N$21*I31) -> 11310.99 | K31: =E27 -> 0.038127084 | L31: =J31*(1+K31) -> 11742.246

Sheet Beta & Cost of Equity
A1: Beta Calculation | R1: Cost of Equity
B5: Date | C5: ASX All Ordinaries Index | D5: ASX All Ordinaries Index - Daily Price Returns | E5: SHL Share Price | F5: SHL - Daily Returns | R5: Date | S5: 10 Year Bond Yield (%)-Rf | T5: Year | U5: Historic ASX 200 Prices | V5: ASX Accumulation Index Returns (Rm)
B6: 43647 | C6: 69660.23 | E6: 27.14 | R6: 41641 | S6: 4.292 | T6: 2014 | U6: 46046.93
B7: 43648 | C7: 69760.82 | D7: =(C7/C6)-1 -> 0.001444009 | E7: 27.24 | F7: =(E7/E6)-1 -> 0.0036845984 | H7: Regression Statistics | R7: 41642 | S7: 4.292 | T7: 2015 | U7: 47788.21 | V7: =(U7/U6)-1 -> 0.037815333
B8: 43649 | C8: 70065.96 | D8: =(C8/C7)-1 -> 0.0043740885 | E8: 27.3 | F8: =(E8/E7)-1 -> 0.0022026432 | H8: Multiple R | I8: 0.49096495 | R8: 41645 | S8: 4.292 | T8: 2016 | U8: 53353.97 | V8: =(U8/U7)-1 -> 0.11646722
B9: 43650 | C9: 70384.08 | D9: =(C9/C8)-1 -> 0.0045402932 | E9: 27.36 | F9: =(E9/E8)-1 -> 0.0021978022 | H9: R Square | I9: 0.24104658 | R9: 41646 | S9: 4.292 | T9: 2017 | U9: 60007.77 | V9: =(U9/U8)-1 -> 0.12471049
B10: 43651 | C10: 70703.89 | D10: =(C10/C9)-1 -> 0.0045437832 | E10: 27.65 | F10: =(E10/E9)-1 -> 0.010599415 | H10: Adjusted R Square | I10: 0.24044567 | R10: 41647 | S10: 4.292 | T10: 2018 | U10: 57887.91 | V10: =(U10/U9)-1 -> -0.035326425
B11: 43654 | C11: 69934.44 | D11: =(C11/C10)-1 -> -0.010882711 | E11: 27.16 | F11: =(E11/E10)-1 -> -0.017721519 | H11: Standard Error | I11: 0.014326452 | R11: 41648 | S11: 4.292 | T11: 2019 | U11: 71813.87 | V11: =(U11/U10)-1 -> 0.24056768
B12: 43655 | C12: 69861.58 | D12: =(C12/C11)-1 -> -0.0010418329 | E12: 27.42 | F12: =(E12/E11)-1 -> 0.0095729013 | H12: Observations | I12: 1265 | R12: 41649 | S12: 4.292 | T12: 2020 | U12: 74424.55 | V12: =(U12/U11)-1 -> 0.036353423
B13: 43656 | C13: 70146.83 | D13: =(C13/C12)-1 -> 0.004083074 | E13: 27.57 | F13: =(E13/E12)-1 -> 0.0054704595 | R13: 41652 | S13: 4.292 | T13: 2021 | U13: 87626.08 | V13: =(U13/U12)-1 -> 0.17738139
B14: 43657 | C14: 70438.19 | D14: =(C14/C13)-1 -> 0.0041535733 | E14: 27.65 | F14: =(E14/E13)-1 -> 0.0029017048 | H14: ANOVA | R14: 41653 | S14: 4.292 | T14: 2022 | U14: 85033.52 | V14: =(U14/U13)-1 -> -0.029586625
B15: 43658 | C15: 70262 | D15: =(C15/C14)-1 -> -0.002501342 | E15: 27.62 | F15: =(E15/E14)-1 -> -0.001084991 | I15: df | J15: SS | K15: MS | L15: F | M15: Significance F | R15: 41654 | S15: 4.292 | T15: 2023 | U15: 86796.56 | V15: =(U15/U14)-1 -> 0.020733471
B16: 43661 | C16: 69821.01 | D16: =(C16/C15)-1 -> -0.0062763656 | E16: 27.66 | F16: =(E16/E15)-1 -> 0.0014482259 | H16: Regression | I16: 1 | J16: 0.082331587 | K16: 0.082331587 | L16: 401.13374 | M16: 1.0348514e-77 | R16: 41655 | S16: 4.292 | T16: 2024 | U16: 87894.32 | V16: =(U16/U15)-1 -> 0.012647506
B17: 43662 | C17: 69713.75 | D17: =(C17/C16)-1 -> -0.0015362138 | E17: 27.7 | F17: =(E17/E16)-1 -> 0.0014461316 | H17: Residual | I17: 1263 | J17: 0.25922724 | K17: 0.00020524722 | R17: 41656 | S17: 4.292
B18: 43663 | C18: 70005.77 | D18: =(C18/C17)-1 -> 0.0041888437 | E18: 27.9 | F18: =(E18/E17)-1 -> 0.0072202166 | H18: Total | I18: 1264 | J18: 0.34155883 | R18: 41659 | S18: 4.292 | V18: =AVERAGE(V7:V16) -> 0.070176346
B19: 43664 | C19: 69709.61 | D19: =(C19/C18)-1 -> -0.0042305084 | E19: 27.82 | F19: =(E19/E18)-1 -> -0.0028673835 | R19: 41660 | S19: 4.292 | U19: Cost Of Equity
B20: 43665 | C20: 70235.78 | D20: =(C20/C19)-1 -> 0.0075480267 | E20: 27.91 | F20: =(E20/E19)-1 -> 0.0032350827 | I20: Coefficients | J20: Standard Error | K20: t Stat | L20: P-value | M20: Lower 95% | N20: Upper 95% | O20: Lower 95.0% | P20: Upper 95.0% | R20: 41661 | S20: 4.292
B21: 43668 | C21: 70184 | D21: =(C21/C20)-1 -> -0.00073723108 | E21: 27.53 | F21: =(E21/E20)-1 -> -0.013615192 | H21: Intercept | I21: -0.00014633896 | J21: 0.00040300771 | K21: -0.36311701 | L21: 0.71657824 | M21: -0.00093697723 | N21: 0.00064429932 | O21: -0.00093697723 | P21: 0.00064429932 | R21: 41662 | S21: 4.292 | U21: Varible
B22: 43669 | C22: 70507.28 | D22: =(C22/C21)-1 -> 0.004606178 | E22: 27.52 | F22: =(E22/E21)-1 -> -0.0003632401 | H22: Beta | I22: 0.74099268 | J22: 0.036997239 | K22: 20.028324 | L22: 1.0348514e-77 | M22: 0.66840986 | N22: 0.81357549 | O22: 0.66840986 | P22: 0.81357549 | R22: 41663 | S22: 4.292 | U22: Rm-Rf | V22: =2.71/100 -> 0.0271
B23: 43670 | C23: 71023.78 | D23: =(C23/C22)-1 -> 0.0073254847 | E23: 27.87 | F23: =(E23/E22)-1 -> 0.012718023 | R23: 41667 | S23: 4.292 | U23: Beta | V23: =I24 -> 0.741
B24: 43671 | C24: 71432.24 | D24: =(C24/C23)-1 -> 0.0057510316 | E24: 28.15 | F24: =(E24/E23)-1 -> 0.010046645 | H24: Beta | I24: 0.741 | R24: 41668 | S24: 4.292 | U24: Rf | V24: =4.292/100 -> 0.04292
B25: 43672 | C25: 71199.36 | D25: =(C25/C24)-1 -> -0.0032601526 | E25: 27.37 | F25: =(E25/E24)-1 -> -0.027708703 | R25: 41669 | S25: 4.292 | U25: Cost Of Equity | V25: =V24+(V23*V22) -> 0.0630011
B26: 43675 | C26: 71531.46 | D26: =(C26/C25)-1 -> 0.0046643678 | E26: 27.78 | F26: =(E26/E25)-1 -> 0.014979905 | R26: 41670 | S26: 4.292
B27: 43676 | C27: 71706.29 | D27: =(C27/C26)-1 -> 0.0024440994 | E27: 28 | F27: =(E27/E26)-1 -> 0.0079193665 | R27: 41673 | S27: 4.292
B28: 43677 | C28: 71378.47 | D28: =(C28/C27)-1 -> -0.0045717049 | E28: 28.04 | F28: =(E28/E27)-1 -> 0.0014285714 | R28: 41674 | S28: 4.292
B29: 43678 | C29: 71122.68 | D29: =(C29/C28)-1 -> -0.0035835736 | E29: 28.1 | F29: =(E29/E28)-1 -> 0.0021398003 | R29: 41675 | S29: 4.292
B30: 43679 | C30: 70854.82 | D30: =(C30/C29)-1 -> -0.0037661685 | E30: 28.34 | F30: =(E30/E29)-1 -> 0.0085409253 | R30: 41676 | S30: 4.292
B31: 43682 | C31: 69452.95 | D31: =(C31/C30)-1 -> -0.019785104 | E31: 27.99 | F31: =(E31/E30)-1 -> -0.012350035 | R31: 41677 | S31: 4.292
B32: 43683 | C32: 67754.3 | D32: =(C32/C31)-1 -> -0.024457564 | E32: 26.98 | F32: =(E32/E31)-1 -> -0.036084316 | R32: 41680 | S32: 4.292
B33: 43684 | C33: 68189.8 | D33: =(C33/C32)-1 -> 0.0064276363 | E33: 27.57 | F33: =(E33/E32)-1 -> 0.02186805 | R33: 41681 | S33: 4.292
B34: 43685 | C34: 68774.03 | D34: =(C34/C33)-1 -> 0.0085677037 | E34: 27.8 | F34: =(E34/E33)-1 -> 0.0083424012 | R34: 41682 | S34: 4.292
B35: 43686 | C35: 68994.27 | D35: =(C35/C34)-1 -> 0.0032023716 | E35: 27.7 | F35: =(E35/E34)-1 -> -0.0035971223 | R35: 41683 | S35: 4.292
B36: 43689 | C36: 69063.73 | D36: =(C36/C35)-1 -> 0.0010067503 | E36: 27.98 | F36: =(E36/E35)-1 -> 0.010108303 | R36: 41684 | S36: 4.292
B37: 43690 | C37: 68840.16 | D37: =(C37/C36)-1 -> -0.003237155 | E37: 28.13 | F37: =(E37/E36)-1 -> 0.0053609721 | R37: 41687 | S37: 4.292
... B1271: 45471 | C1271: 100125.06 | D1271: =(C1271/C1270)-1 -> 0.0014070198 | E1271: 26.3 | F1271: =(E1271/E1270)-1 -> -0.0026545317 | R1271: 43467 | S1271: 4.292
R1272: 43468 | S1272: 4.292
R1273: 43469 | S1273: 4.292
R1274: 43472 | S1274: 4.292
R1275: 43473 | S1275: 4.292
R1276: 43474 | S1276: 4.292
...

Sheet Cost Of Debt & WACC
A2: Cost Of Debt Calculation | B2: 2024 | C2: 2023 | H2: Weight Calculation | I2: $ | J2: %
A3: Interest Expense | B3: 100.6 | H3: Total Debt | I3: 2987.9 | J3: =(I3/I5)*100 -> 27.398102
A4: Short Term Debt | B4: 297.5 | H4: Total Equity | I4: 7917.6 | J4: =(I4/I5)*100 -> 72.601898
A5: Long Term Debt | B5: 2690.4 | C5: 1673.5 | H5: Total Value | I5: 10905.5 | J5: 1
A6: Total Debt (FY2024) | B6: =B5+B4 -> 2987.9
A7: Average Debt (FY2024) | B7: =(B6+C5)/2 -> 2330.7
A8: Cost Of Debt Calculation | B8: =B3/B7 -> 0.043162998
A9: Income Tax Expense | B9: 186.84
A10: Income Before Tax | B10: 730.65
A11: Effective Tax Rate | B11: =B9/B10 -> 0.25571751
A12: Cost Of Debt *(1-t) | B12: =B8*(1-B11) -> 0.032125464
A15: Cost of Equity | B15: 0.063
A16: Cost of Debt | B16: 0.04
A17: Weight of Debt | B17: 27.3981
A18: Weight of Equity | B18: 72.6019
A20: The Weighted Average Cost Of Capital (WACC) is calculated as follows
A21: WACC=(Weight of Equity*Cost of Equity)+(Weight of Debt*After Tax Cost of Debt)
B22: =0.0545 -> 0.0545
